Workbook
Name fed_ltcg_rate: Inputs!$B$5
Name niit_rate: Inputs!$B$7
Name eff_fed_rate: Inputs!$B$8
Name state_rate: Inputs!$B$9
Name combined_rate: Inputs!$B$10
Name serb_date: Inputs!$B$14
Name serb_basis: Inputs!$B$15
Name serb_shares: Inputs!$B$17
Name qsbs_5yr_date: Inputs!$B$19
Name lockup_date: Inputs!$B$41
Name lockup_price: Inputs!$B$42
Name ph3_date: Inputs!$B$47
Name evecxia_ph2_date: Inputs!$B$48
Name evecxia_price: Inputs!$B$30
Name evecxia_purchase: Inputs!$B$29

Sheet README
A1: LBRX QSBS & Evecxia Scenario Model — README
A3: WHAT THIS MODEL DOES:
A4: This Excel model analyzes tax scenarios for LBRX (LB Pharmaceuticals) Series B/C investors under QSBS rules, including §1202 exclusion and §1045 rollover into Evecxia Therapeutics.
A6: HOW TO USE:
A7: 1. Go to the Inputs tab
A8: 2. Modify investor-specific assumptions in light blue cells:
A9: - Federal LTCG rate, NIIT, state tax rate (rows 5-9)
A10: - Series B cost basis and share price (rows 15-16)
A11: - Lock-up price (row 42) — EDITABLE to test different sale prices
A12: - Scenario valuations (rows 52-65) — Adjust based on your comp analysis
A13: 3. Review Scenarios tab for 6 tax outcome scenarios
A14: 4. Check Outputs dashboard for summary comparison
... A29: Generated: 2026-02-13 23:27

Sheet Inputs
A1: LBRX QSBS & Evecxia Scenario Model
A2: Inputs & Assumptions
A4: INVESTOR TAX PROFILE
A5: Federal LTCG Rate | B5: 0.2
A6: NIIT (3.8%) Applies? | B6: YES
A7: NIIT Rate | B7: =IF(B6="YES",0.038,0)
A8: Effective Federal Rate | B8: =B5+B7
A9: State Tax Rate | B9: 0
A10: Combined Tax Rate | B10: =B8+B9
A11: Federal Ordinary Income Rate | B11: 0.37
A13: SERIES B INVESTMENT
A14: Series B Invest Date | B14: 44684
A15: Series B Cost Basis ($) | B15: 100000
A16: Series B Cost Per Share | B16: 24
A17: Series B Shares Acquired | B17: =B15/B16
A18: Series B QSBS Eligible | B18: YES
A19: QSBS 5-Year Completion Date | B19: =B14+1826
A21: SERIES C INVESTMENT (optional)
A22: Series C Invest Date
A23: Series C Cost Basis ($)
A24: Series C Cost Per Share | B24: 36.44
A25: Series C Shares Acquired | B25: =IF(B23="","",B23/B24)
A26: Series C QSBS Eligible | B26: NO
A28: EVECXIA INVESTMENT (§1045)
A29: Evecxia Purchase Date | B29: 46123
A30: Evecxia Share Price | B30: 0.1069
A31: Amount Reinvested | B31: =B15
A32: Evecxia Shares Acquired | B32: =B31/B30
A33: Evecxia QSBS Eligible | B33: YES
A34: Evecxia Pre-Money Valuation | B34: 14000000
A35: Evecxia Post-Money Valuation | B35: 30000000
A36: Evecxia Total Shares at SerA Close | B36: =B35/B30
A38: MARKET / IPO DETAILS
A39: IPO Date | B39: 45912
A40: IPO Price | B40: 15
A41: Lock-Up Release Date | B41: 46093
A42: Current / Lock-Up Price | B42: 24.22
A43: Shares Outstanding (post-IPO) | B43: 25300000
A44: Shares Outstanding (post-PIPE) | B44: 30000000
A46: CLINICAL TIMELINE
...

Sheet Timeline
A1: Date | B1: Event | C1: Days from Series B | D1: QSBS Status | E1: Notes
A2: =serb_date | B2: Series B Closes → QSBS Clock Starts | C2: =A2-serb_date | D2: Day 0 | E2: QSBS holding period begins
A3: =serb_date+180 | B3: 6-Month §1045 Eligibility Threshold Met | C3: =A3-serb_date | D3: 6 months | E3: §1045 rollover now available if sold
A4: =Inputs!$B$39 | B4: LBRX IPO at $15.00/share | C4: =A4-serb_date | D4: IPO event | E4: Series B converts to common, heavy dilution
A5: =lockup_date | B5: Lock-Up Release (180 days post-IPO) | C5: =A5-serb_date | D5: ~46 months | E5: Series B can sell, but < 5 years → NO §1202
A6: =evecxia_purchase | B6: Evecxia Purchase (§1045 scenario) | C6: =A6-serb_date | D6: Within 60d of lock-up | E6: If §1045 rollover executed
A7: =qsbs_5yr_date | B7: 5-YEAR QSBS THRESHOLD MET (Series B) | C7: =A7-serb_date | D7: 1826 days (5 yrs) | E7: §1202 exclusion NOW available
A8: =Inputs!$B$49 | B8: Evecxia IPO (estimated) | C8: =A8-serb_date | D8: Pre-readout | E8: If Evecxia goes public Q2 2027
A9: =ph3_date | B9: LBRX Phase 3 Topline (estimated) | C9: =A9-serb_date | D9: ~5.4 years | E9: CRITICAL: After May 3, 2027 → §1202 available
A10: =evecxia_ph2_date | B10: Evecxia Phase 2 OCD Readout (estimated) | C10: =A10-serb_date | D10: ~5.45 years | E10: §1045→§1202 chain value inflection
A13: KEY FLAGS (formula-driven):
A14: Lock-up sale before 5-year QSBS? | B14: =IF(lockup_date<qsbs_5yr_date,"YES - NO §1202 AVAILABLE","NO - §1202 AVAILABLE") | E14: Critical for tax planning
A15: Phase 3 readout after QSBS 5-year? | B15: =IF(ph3_date>qsbs_5yr_date,"YES - §1202 AVAILABLE","NO - TOO EARLY") | E15: Can hold through Ph3 with §1202
A16: §1045 holding > 6 months at lock-up? | B16: =IF((lockup_date-serb_date)>180,"YES - §1045 ELIGIBLE","NO") | E16: Series B meets 6-month requirement
A17: Evecxia purchase within 60 days? | B17: =IF((evecxia_purchase-lockup_date)<=60,"YES - WITHIN WINDOW","NO - TOO LATE") | E17: Must reinvest within 60 days
A18: Tacked holding at Evecxia sale (days) | B18: =evecxia_ph2_date-serb_date | E18: Holding period tacks from Series B date
A19: Tacked holding at Evecxia sale (years) | B19: =(evecxia_ph2_date-serb_date)/365.25 | E19: > 5 years → §1202 on Evecxia sale

Sheet Comps
A1: COMP SET 1: LBRX POST-PHASE 3 POSITIVE READOUT VALUATION
A2: Company | B2: Ticker | C2: Indication | D2: Stage | E2: Event | F2: Event Date | G2: Mkt Cap ($M) | H2: EV ($M) | I2: % Move | J2: Rationale | K2: Source
A3: Karuna Therapeutics | B3: KRTX | C3: Schizophrenia (KarXT) | D3: FDA review stage | E3: BMY Acquisition Announced | F3: Dec 22 2023 | G3: 14000 | H3: 12700 | I3: 0.53 | J3: Premier schizophrenia comp, 330 per share | K3: BMY press release Dec 22, 2023
A4: Intra-Cellular Therapies | B4: ITCI | C4: Schizophrenia + Bipolar (Caplyta) | D4: FDA approved, commercial | E4: JNJ Acquisition Announced | F4: Jan 13 2025 | G4: 14600 | H4: 14600 | I4: 0.39 | J4: CNS antipsychotic, 132 per share, 2024 revenue 481M | K4: JNJ press release Jan 13, 2025
A5: Cerevel Therapeutics | B5: CERE | C5: Schizophrenia (emraclidine) | D5: Phase 2 (pre-data at acquisition) | E5: AbbVie Acquisition Announced | F5: Dec 6 2023 | G5: 8700 | H5: 8700 | I5: 0.22 | J5: CAUTION: Emraclidine Ph2 failed Nov 2024, 3.5B impairment | K5: AbbVie press release Dec 6, 2023
A6: Neurocrine Biosciences | B6: NBIX | C6: Tardive dyskinesia (Ingrezza) | D6: Commercial (approved 2017) | E6: Current Market Cap | F6: Feb 13 2026 | G6: 12300 | H6: 12300 | I6: N/A | J6: CNS commercial comp, long-term value ceiling | K6: Yahoo Finance Feb 2026 (updated from 15B)
A7: Acadia Pharmaceuticals | B7: ACAD | C7: Parkinson's psychosis (Nuplazid) | D7: Commercial (approved 2016) | E7: Current Market Cap | F7: Feb 13 2026 | G7: 4300 | H7: 4300 | I7: N/A | J7: Psychiatric niche indication, single-product CNS | K7: Yahoo Finance Feb 2026 (updated from 3.8B)
A9: DERIVED LBRX POSITIVE READOUT RANGE:
A10: Low | B10: $1.5B mkt cap (~$50/share) | J10: Discount to Cerevel emraclidine-only; single-asset Phase 3 positive but pre-NDA
A11: Base | B11: $3.0B mkt cap (~$100/share) | J11: Between ITCI at approval ($1.8B historical) and Cerevel ($8.7B); accounts for positive Phase 3 + pipeline
A12: High | B12: $5.0B mkt cap (~$165/share) | J12: Approaches Karuna pre-deal valuation; assumes very strong data + M&A premium expectations
A14: COMP SET 2: LBRX POST-PHASE 3 NEGATIVE READOUT / FAILURE
A15: Company | B15: Ticker | C15: Indication | D15: Stage | E15: Event | F15: Event Date | G15: Mkt Cap ($M) | H15: EV ($M) | I15: % Move | J15: Rationale | K15: Source
A16: Minerva Neurosciences | B16: NERV | C16: Schizophrenia negative symptoms | D16: Phase 3 failure | E16: Roluperidone Ph3 Failure | F16: May 29 2020 | G16: 100 | H16: 100 | I16: -0.81 | J16: Direct schizophrenia Ph3 failure, 550M to 100M | K16: Seeking Alpha, Minerva PR May 29, 2020
A17: Sage Therapeutics | B17: SAGE | C17: Major depressive disorder | D17: Phase 3 failure | E17: SAGE-217 MOUNTAIN Failure | F17: Dec 5 2019 | G17: 3700 | H17: 3700 | I17: -0.6 | J17: CNS psych Ph3 failure in depression, 8B to 3.7B | K17: Sage press release Dec 5, 2019
A19: DERIVED LBRX NEGATIVE READOUT RANGE:
A20: Low | B20: $100M mkt cap (~$3.30/share) | J20: Minerva-style wipeout; total loss of schizophrenia thesis, bipolar program too early
A21: Base | B21: $200M mkt cap (~$6.60/share) | J21: Cash floor (~$300M+ cash) minus burn; bipolar program provides option value
A22: High | B22: $350M mkt cap (~$11.50/share) | J22: Modest decline; if failure is dose-related or borderline, market may give credit for re-try + bipolar pipeline
A24: COMP SET 3: EVECXIA PRE-PHASE 2 READOUT / IPO VALUATION
A25: Company | B25: Ticker | C25: Indication | D25: Stage | E25: Event | F25: Event Date | G25: Mkt Cap ($M) | H25: EV ($M) | I25: % Move | J25: Rationale | K25: Source
A26: Karuna Therapeutics | B26: KRTX | C26: Schizophrenia (KarXT) | D26: Pre-Phase 2 data | E26: IPO | F26: Jul 1 2019 | G26: 414 | H26: 414 | I26: N/A | J26: Novel mechanism psych company at IPO, Phase 2 data came Nov 2019 | K26: Karuna S-1, Streetwise Reports Nov 2019
A27: Axsome Therapeutics | B27: AXSM | C27: Multi-indication CNS platform | D27: Early clinical | E27: IPO | F27: Jan 1 2015 | G27: 155 | H27: 155 | I27: N/A | J27: Psych multi-indication platform, IPOd small, re-rated to 9.4B by 2026 | K27: StockAnalysis.com
A29: DERIVED EVECXIA IPO RANGE (Q2 2027):
A30: Low | B30: $150M post-money | J30: Conservative; Phase 1 complete, OCD Phase 2 enrolling, no data yet. Reflects Series A step-up.
A31: Base | B31: $400M post-money | J31: In line with Karuna at IPO; assumes strong investor interest in serotonin platform + OCD thesis
A32: High | B32: $750M post-money | J32: Assumes pre-data hype cycle comparable to Karuna pre-Phase 2; M&A interest creates premium
A34: COMP SET 4: EVECXIA POST-PHASE 2 POSITIVE VS NEGATIVE OUTCOMES
A35: Company | B35: Ticker | C35: Indication | D35: Stage | E35: Event | F35: Event Date | G35: Mkt Cap ($M) | H35: EV ($M) | I35: % Move | J35: Rationale | K35: Source
A36: Karuna Therapeutics | B36: KRTX | C36: Schizophrenia (KarXT) | D36: Phase 2 positive | E36: Phase 2 Data Announced | F36: Nov 18 2019 | G36: 2000 | H36: 2000 | I36: 3.75 | J36: Premier Phase 2 psych readout comp, 11.6-pt PANSS reduction, $414M → $2B in 1 day | K36: Karuna press release Nov 18, 2019
A37: Sage Therapeutics | B37: SAGE | C37: Postpartum depression | D37: Phase 2 success | E37: Phase 2 PPD Success | F37: Jan 1 2018 | G37: 1500 | H37: 1500 | I37: N/A | J37: Phase 2 psych success trajectory, rose from ~$80 to ~$190 in 2019 | K37: Sage press releases 2018-2019
A38: Axsome Therapeutics | B38: AXSM | C38: Major depressive disorder | D38: Phase 3 MDD success | E38: AXS-05 Ph3 MDD Success | F38: Dec 1 2019 | G38: 3800 | H38: 3800 | I38: N/A | J38: Depression Phase 3 success, grew from ~$155M at IPO to ~$3.8B end 2019 | K38: Axsome press releases
A40: DERIVED EVECXIA POST-PHASE 2 POSITIVE RANGE:
A41: Low | B41: $800M | J41: Modest positive; OCD data supportive but not blockbuster
A42: Base | B42: $1.5B | J42: Clearly positive Phase 2; validates serotonin platform; M&A interest intensifies
A43: High | B43: $3.0B | J43: Karuna-style blowout; data exceeds expectations; bidding war / strategic premium
A45: DERIVED EVECXIA POST-PHASE 2 NEGATIVE RANGE:
A46: Low | B46: $50M | J46: Cash-floor wipeout; OCD thesis invalidated
A47: Base | B47: $120M | J47: Failed primary but secondary signals; platform retains option value in other indications
A48: High | B48: $250M | J48: Borderline miss; dose/endpoint issue; still fundable

Sheet Scenarios
A1: SCENARIO ANALYSIS
A3: Metric | B3: S1: Lock-Up Sale | C3: S2: Ph3+ Hold | D3: S3: Ph3- Hold | E3: S4: Dual Lot Lock-Up | F3: S5: §1045→Eve Ph2+ | G3: S6: §1045→Eve Ph2-
A4: Sale Date | B4: =lockup_date | C4: =ph3_date | D4: =ph3_date | E4: =lockup_date | F4: =evecxia_ph2_date | G4: =evecxia_ph2_date
A5: Sale Price/Share | B5: =lockup_price | C5: =Inputs!$B$53 | D5: =Inputs!$B$56 | E5: =lockup_price | F5: N/A (Evecxia) | G5: N/A (Evecxia)
A6: Shares Sold | B6: =serb_shares | C6: =serb_shares | D6: =serb_shares | E6: =serb_shares+B25 | F6: Evecxia | G6: Evecxia
A7: Gross Proceeds | B7: =serb_shares*lockup_price | C7: =serb_shares*Inputs!$B$53 | D7: =serb_shares*Inputs!$B$56 | E7: =B9+C9 | F7: =Inputs!$B$65*0.0026*Inputs!$B$59 | G7: =Inputs!$B$65*0.0026*Inputs!$B$62
A8: Cost Basis | B8: =serb_basis | C8: =serb_basis | D8: =serb_basis | E8: =serb_basis+C25 | F8: =serb_basis | G8: =serb_basis
A9: Gross Gain/(Loss) | B9: =B9-B10 | C9: =C9-C10 | D9: =D9-D10 | E9: =E9-E10 | F9: =F9-F10 | G9: =G9-G10
A11: Holding Period (days) | B11: =lockup_date-serb_date | C11: =ph3_date-serb_date | D11: =ph3_date-serb_date | E11: Varies | F11: =evecxia_ph2_date-serb_date | G11: =evecxia_ph2_date-serb_date
A12: Holding Period (years) | B12: =B13/365.25 | C12: =C13/365.25 | D12: =D13/365.25 | E12: Varies | F12: =F13/365.25 | G12: =G13/365.25
A13: Long-Term? | B13: =IF(B13>365,"YES","NO") | C13: =IF(C13>365,"YES","NO") | D13: =IF(D13>365,"YES","NO") | E13: YES | F13: YES | G13: YES
A14: QSBS 5-Year Met? | B14: =IF(B13>=1826,"YES","NO") | C14: =IF(C13>=1826,"YES","NO") | D14: =IF(D13>=1826,"YES","NO") | E14: See detail | F14: =IF(F13>=1826,"YES","NO") | G14: =IF(G13>=1826,"YES","NO")
A16: §1202 Exclusion Amount | B16: =IF(B16="YES",MIN(B11,10000000),0) | C16: =IF(C16="YES",MIN(C11,10000000),0) | D16: =IF(D16="YES",MAX(0,MIN(D11,10000000)),0) | E16: See detail | F16: =IF(F16="YES",MIN(F11,10000000),0) | G16: =IF(G16="YES",MIN(MAX(0,G11),10000000),0)
A17: §1045 Deferred Gain | B17: 0 | C17: 0 | D17: 0 | E17: 0 | F17: =B11 | G17: =B11
A18: Taxable Gain | B18: =MAX(0,B11-B18-B19) | C18: =MAX(0,C11-C18-C19) | D18: =MAX(0,D11-D18-D19) | E18: See detail | F18: =MAX(0,F11-F18-F19) | G18: =MAX(0,G11-G18-G19)
A20: Federal LTCG Tax | B20: =B20*eff_fed_rate | C20: =C20*eff_fed_rate | D20: =D20*eff_fed_rate | E20: See detail | F20: =F20*eff_fed_rate | G20: =G20*eff_fed_rate
A21: State Tax | B21: =B20*state_rate | C21: =C20*state_rate | D21: =D20*state_rate | E21: See detail | F21: =F20*state_rate | G21: =G20*state_rate
A22: Total Tax | B22: =B22+B23 | C22: =C22+C23 | D22: =D22+D23 | E22: See detail | F22: =F22+F23 | G22: =G22+G23
A24: Net After-Tax Proceeds | B24: =B9-B24 | C24: =C9-C24 | D24: =D9-D24 | E24: See detail | F24: =F9-F24 | G24: =G9-G24
A25: MOIC (Multiple on Investment) | B25: =B26/serb_basis | C25: =C26/serb_basis | D25: =D26/serb_basis | E25: Varies | F25: =F26/serb_basis | G25: =G26/serb_basis
A26: Effective Tax Rate | B26: =IF(B11>0,B24/B11,0) | C26: =IF(C11>0,C24/C11,0) | D26: =IF(D11>0,D24/D11,0) | E26: Varies | F26: =IF(F11>0,F24/F11,0) | G26: =IF(G11>0,G24/G11,0)
A29: SCENARIO S4 DETAIL: Series B + Series C Lot-by-Lot at Lock-Up
A30: Metric | B30: Series B Lot | C30: Series C Lot | D30: Total
A31: Sale Date | B31: =lockup_date | C31: =lockup_date | D31: Same
A32: Sale Price/Share | B32: =lockup_price | C32: =lockup_price | D32: Same
A33: Shares Sold | B33: =serb_shares | C33: =IF(Inputs!$B$23="","",Inputs!$B$25) | D33: =B33+C33
A34: Gross Proceeds | B34: =B{r1}*lockup_price | C34: =C{r1}*lockup_price | D34: =B34+C34
A35: Cost Basis | B35: =serb_basis | C35: =IF(Inputs!$B$23="","",Inputs!$B$23) | D35: =B35+C35
A36: Gross Gain | B36: =B{r1}-B{r2} | C36: =C{r1}-C{r2} | D36: =B36+C36
A37: Holding Period (days) | B37: =lockup_date-serb_date | C37: =IF(Inputs!$B$22="","",lockup_date-Inputs!$B$22) | D37: Varies
A38: QSBS Eligible? | B38: YES | C38: NO | D38: Mixed
A39: QSBS 5-Year Met? | B39: =IF(B{r1}>=1826,"YES","NO") | C39: N/A | D39: Mixed
A40: §1202 Exclusion | B40: =IF(B{r1}="YES",MIN(B{r3},10000000),0) | C40: 0 | D40: =B40+C40
A41: Taxable Gain | B41: =MAX(0,B{r4}-B{r1}) | C41: =MAX(0,C{r4}) | D41: =B41+C41
A42: Tax Due | B42: =B{r1}*combined_rate | C42: =C{r1}*combined_rate | D42: =B42+C42
A43: Net After-Tax | B43: =B{r8}-B{r1} | C43: =C{r8}-C{r1} | D43: =B43+C43
A46: SCENARIOS S5/S6 DETAIL: §1045 Rollover → Evecxia (Two-Leg Journey)
A47: Leg / Metric | B47: S5: Positive Ph2 | C47: S6: Negative Ph2
A48: LEG 1: LBRX SALE AT LOCK-UP
A49: LBRX Sale Date | B49: =lockup_date | C49: =lockup_date
...

Sheet TaxLogic
A1: TAX LOGIC ENGINE
A2: All tax calculations reference Inputs tab via named ranges
A4: SECTION 1: STANDARD CAPITAL GAINS TAX CALCULATOR
A5: Example Inputs (for illustration):
A6: Proceeds | B6: 100000
A7: Cost Basis | B7: 80000
A8: Holding Period (days) | B8: 400
A10: CALCULATED:
A11: Gain / (Loss) | B11: =B6-B8
A12: Long-Term (>365 days)? | B12: =IF(B10>365,"YES","NO")
A13: Tax Rate Applied | B13: =IF(B15="YES",combined_rate,Inputs!$B$11) | C13: ← LTCG if >1yr, else ordinary
A14: Tax Due | B14: =MAX(0,B13)*B16
A16: SECTION 2: §1202 QSBS ELIGIBILITY CHECK
A17: Inputs (example):
A18: Stock QSBS Eligible? | B18: YES
A19: Holding Period (days) | B19: 2000
A20: Gain Amount | B20: 500000
A21: Original Basis | B21: 100000
A23: ELIGIBILITY CHECKS:
A24: Check A: Stock is QSBS? | B24: =IF(B23="YES","PASS","FAIL") | C24: ← Must be QSBS
A25: Check B: Held ≥ 5 years (1826 days)? | B25: =IF(B25>=1826,"PASS","FAIL") | C25: ← 5 years = 1826 days
A26: Overall Eligible? | B26: =IF(AND(B32="PASS",B34="PASS"),"YES - §1202 AVAILABLE","NO")
A28: §1202 EXCLUSION CALCULATION:
A29: Exclusion Cap | B29: =MAX(10000000,10*B28) | C29: ← Greater of $10M or 10× basis
A30: Gain to Exclude | B30: =IF(B36="YES - §1202 AVAILABLE",MIN(B27,B40),0)
A31: Remaining Taxable Gain | B31: =MAX(0,B27-B42)
A32: Tax on Remaining Gain | B32: =B44*combined_rate
A34: SECTION 3: §1045 ROLLOVER CALCULATOR (8-STEP WALKTHROUGH)
A35: STEP 1: DETERMINE §1045 ELIGIBILITY
A36: Inputs (example):
A37: Original stock QSBS? | B37: YES
A38: Held original > 6 months (180 days)? | B38: YES
A39: Replacement purchased within 60 days? | B39: YES
A40: Replacement stock is QSBS? | B40: YES
A42: All §1045 Requirements Met? | B42: =IF(AND(B53="YES",B55="YES",B57="YES",B59="YES"),"YES - §1045 ELIGIBLE","NO")
A44: STEP 2: CALCULATE ORIGINAL SALE PROCEEDS & GAIN
A45: Gross proceeds from sale | B45: 100008
A46: Cost basis | B46: 100000
A47: Realized gain | B47: =B67-B69
A49: STEP 3: APPLY §1045 DEFERRAL
...

Sheet Outputs
A1: OUTPUTS DASHBOARD
A3: KEY FLAGS
A4: QSBS 5-year met at lock-up? | B4: =IF(lockup_date>=qsbs_5yr_date,"YES","NO")
A5: QSBS 5-year met at Phase 3 readout? | B5: =IF(ph3_date>=qsbs_5yr_date,"YES","NO")
A6: §1045 eligible? | B6: =IF(AND((lockup_date-serb_date)>180,Inputs!$B$33="YES"),"YES","NO")
A7: §1045 → §1202 chain achievable? | B7: =IF(AND(B6="YES",(evecxia_ph2_date-serb_date)>=1826),"YES","NO")
A10: SCENARIO COMPARISON
A11: Metric | B11: S1: Lock-Up | C11: S2: Ph3+ | D11: S3: Ph3- | E11: S4: Dual Lot | F11: S5: Eve+ | G11: S6: Eve-
A12: Gross Proceeds | B12: =Scenarios!B9 | C12: =Scenarios!C9 | D12: =Scenarios!D9 | E12: =Scenarios!D36 | F12: =Scenarios!F9 | G12: =Scenarios!G9
A13: Gain | B13: =Scenarios!B11 | C13: =Scenarios!C11 | D13: =Scenarios!D11 | E13: =Scenarios!D38 | F13: =Scenarios!F11 | G13: =Scenarios!G11
A14: §1202 Exclusion | B14: =Scenarios!B18 | C14: =Scenarios!C18 | D14: =Scenarios!D18 | E14: =Scenarios!D47 | F14: =Scenarios!F18 | G14: =Scenarios!G18
A15: Total Tax | B15: =Scenarios!B24 | C15: =Scenarios!C24 | D15: =Scenarios!D24 | E15: =Scenarios!D49 | F15: =Scenarios!F24 | G15: =Scenarios!G24
A16: Net After-Tax | B16: =Scenarios!B26 | C16: =Scenarios!C26 | D16: =Scenarios!D26 | E16: =Scenarios!D50 | F16: =Scenarios!F26 | G16: =Scenarios!G26
A17: MOIC | B17: =Scenarios!B27 | C17: =Scenarios!C27 | D17: =Scenarios!D27 | E17: Varies | F17: =Scenarios!F27 | G17: =Scenarios!G27
A20: SENSITIVITY ANALYSIS: LBRX Price vs Tax Treatment
A21: Tax Treatment | B21: $5 | C21: $10 | D21: $15 | E21: $20 | F21: $30 | G21: $50 | H21: $100
A22: No QSBS (standard LTCG) | B22: =serb_shares*5-(serb_shares*5-serb_basis)*combined_rate | C22: =serb_shares*10-(serb_shares*10-serb_basis)*combined_rate | D22: =serb_shares*15-(serb_shares*15-serb_basis)*combined_rate | E22: =serb_shares*20-(serb_shares*20-serb_basis)*combined_rate | F22: =serb_shares*30-(serb_shares*30-serb_basis)*combined_rate | G22: =serb_shares*50-(serb_shares*50-serb_basis)*combined_rate | H22: =serb_shares*100-(serb_shares*100-serb_basis)*combined_rate
A23: QSBS §1202 Excluded | B23: =serb_shares*5-MAX(0,(serb_shares*5-serb_basis-10000000))*combined_rate | C23: =serb_shares*10-MAX(0,(serb_shares*10-serb_basis-10000000))*combined_rate | D23: =serb_shares*15-MAX(0,(serb_shares*15-serb_basis-10000000))*combined_rate | E23: =serb_shares*20-MAX(0,(serb_shares*20-serb_basis-10000000))*combined_rate | F23: =serb_shares*30-MAX(0,(serb_shares*30-serb_basis-10000000))*combined_rate | G23: =serb_shares*50-MAX(0,(serb_shares*50-serb_basis-10000000))*combined_rate | H23: =serb_shares*100-MAX(0,(serb_shares*100-serb_basis-10000000))*combined_rate

Sheet Sources
A1: # | B1: Source | C1: URL | D1: Category | E1: Date Accessed
A2: 1 | B2: LBRX Current Stock Price | C2: https://finance.yahoo.com/quote/LBRX/ | D2: Market Data | E2: 2026-02-13
A3: 2 | B3: LBRX IPO Announcement | C3: https://www.cooley.com/news/coverage/2025/2025-09-12-lb-pharmaceuticals-announces-$285-million-upsized-ipo | D3: Press Release | E3: 2026-02-13
A4: 3 | B4: LBRX Phase 2 ILLUMINATE-1 | C4: https://www.globenewswire.com/news-release/2026/01/26/3225570/0/en/LB-Pharmaceuticals-Initiates-Phase-2-ILLUMINATE-1-Trial-in-Bipolar-Depression-Expanding-LB-102-Development-Program.html | D4: Clinical Data | E4: 2026-02-13
A5: 4 | B5: LBRX PIPE Financing Feb 2026 | C5: https://www.stocktitan.net/news/LBRX/lb-pharmaceuticals-announces-100-0-million-private-oct35p3986tv.html | D5: Press Release | E5: 2026-02-13
A6: 5 | B6: Karuna BMY Acquisition | C6: https://news.bms.com/news/details/2023/Bristol-Myers-Squibb-Strengthens-Neuroscience-Portfolio-with-Acquisition-of-Karuna-Therapeutics/default.aspx | D6: Comp Valuation | E6: 2026-02-13
A7: 6 | B7: ITCI JNJ Acquisition | C7: https://www.jnj.com/media-center/press-releases/johnson-johnson-strengthens-neuroscience-leadership-with-acquisition-of-intra-cellular-therapies-inc | D7: Comp Valuation | E7: 2026-02-13
A8: 7 | B8: Cerevel AbbVie Acquisition | C8: https://news.abbvie.com/2023-12-06-AbbVie-to-Acquire-Cerevel-Therapeutics-in-Transformative-Transaction-to-Strengthen-Neuroscience-Pipeline | D8: Comp Valuation | E8: 2026-02-13
A9: 8 | B9: Cerevel Emraclidine Ph2 Failure | C9: https://news.abbvie.com/2024-11-11-AbbVie-Provides-Update-on-Phase-2-Results-for-Emraclidine-in-Schizophrenia | D9: Comp Valuation | E9: 2026-02-13
A10: 9 | B10: IRS §1202 QSBS Rules | C10: https://www.irs.gov/instructions/i1040sd (Schedule D instructions) | D10: Tax Authority | E10: 2026-02-13
A11: 10 | B11: IRS §1045 Rollover Rules | C11: https://www.irs.gov/publications/p550 (Investment Income and Expenses) | D11: Tax Authority | E11: 2026-02-13
