Workbook
Name fed_ltcg_rate: Inputs!$B$5
Name niit_rate: Inputs!$B$7
Name eff_fed_rate: Inputs!$B$8
Name state_rate: Inputs!$B$9
Name combined_rate: Inputs!$B$10
Name serb_date: Inputs!$B$14
Name serb_basis: Inputs!$B$15
Name serb_shares: Inputs!$B$17
Name qsbs_5yr_date: Inputs!$B$19
Name lockup_date: Inputs!$B$41
Name lockup_price: Inputs!$B$42
Name ph3_date: Inputs!$B$47
Name evecxia_ph2_date: Inputs!$B$48
Name evecxia_price: Inputs!$B$30
Name evecxia_purchase: Inputs!$B$29

Sheet README
A1: LBRX QSBS & Evecxia Scenario Model — README
A3: WHAT THIS MODEL DOES:
A4: This Excel model analyzes tax scenarios for LBRX (LB Pharmaceuticals) Series B/C investors under QSBS rules, including §1202 exclusion and §1045 rollover into Evecxia Therapeutics.
A6: HOW TO USE:
A7: 1. Go to the Inputs tab
A8: 2. Modify investor-specific assumptions in light yellow cells:
A9: - Federal LTCG rate, NIIT, state tax rate (rows 5-9)
A10: - Series B cost basis and share price (rows 15-16)
A11: - Lock-up price (row 42) — EDITABLE to test different sale prices
A12: - Scenario valuations (rows 52-65) — Adjust based on your comp analysis
A13: 3. Review Scenarios tab for 6 tax outcome scenarios
A14: 4. Check Decision Matrix for probability-weighted analysis
... A30: Generated: 2026-02-14 08:23

Sheet Inputs
A1: LBRX QSBS & Evecxia Scenario Model
A2: Inputs & Assumptions
A4: INVESTOR TAX PROFILE
A5: Federal LTCG Rate | B5: 0.2
A6: NIIT (3.8%) Applies? | B6: YES
A7: NIIT Rate | B7: =IF(B6="YES",0.038,0)
A8: Effective Federal Rate | B8: =B5+B7
A9: State Tax Rate | B9: 0
A10: Combined Tax Rate | B10: =B8+B9
A11: Federal Ordinary Income Rate | B11: 0.37
A13: SERIES B INVESTMENT
A14: Series B Invest Date | B14: 44684
A15: Series B Cost Basis ($) | B15: 100000
A16: Series B Cost Per Share | B16: 24
A17: Series B Shares Acquired | B17: =B15/B16
A18: Series B QSBS Eligible | B18: YES
A19: QSBS 5-Year Completion Date | B19: =B14+1826
A21: SERIES C INVESTMENT (optional)
A22: Series C Invest Date
A23: Series C Cost Basis ($)
A24: Series C Cost Per Share | B24: 36.44
A25: Series C Shares Acquired | B25: =IF(B23="","",B23/B24)
A26: Series C QSBS Eligible | B26: NO
A28: EVECXIA INVESTMENT (§1045)
A29: Evecxia Purchase Date | B29: 46123
A30: Evecxia Share Price | B30: 0.1069
A31: Amount Reinvested | B31: =B15
A32: Evecxia Shares Acquired | B32: =B31/B30
A33: Evecxia QSBS Eligible | B33: YES
A34: Evecxia Pre-Money Valuation | B34: 14000000
A35: Evecxia Post-Money Valuation | B35: 30000000
A36: Evecxia Total Shares at SerA Close | B36: =B35/B30
A38: MARKET / IPO DETAILS
A39: IPO Date | B39: 45912
A40: IPO Price | B40: 15
A41: Lock-Up Release Date | B41: 46093
A42: Current / Lock-Up Price | B42: 24.22
A43: Shares Outstanding (post-IPO) | B43: 25300000
A44: Shares Outstanding (post-PIPE) | B44: 30000000
A46: CLINICAL TIMELINE
...

Sheet Timeline
A1: Date | B1: Event | C1: Days from Series B | D1: QSBS Status | E1: Notes
A2: =serb_date | B2: Series B Closes → QSBS Clock Starts | C2: =A2-serb_date | D2: Day 0 | E2: QSBS holding period begins
A3: =serb_date+180 | B3: 6-Month §1045 Eligibility Threshold Met | C3: =A3-serb_date | D3: 6 months | E3: §1045 rollover now available if sold
A4: =Inputs!$B$39 | B4: LBRX IPO at $15.00/share | C4: =A4-serb_date | D4: IPO event | E4: Series B converts to common, heavy dilution
A5: =lockup_date | B5: Lock-Up Release (180 days post-IPO) | C5: =A5-serb_date | D5: ~46 months | E5: Series B can sell, but < 5 years → NO §1202
A6: =evecxia_purchase | B6: Evecxia Purchase (§1045 scenario) | C6: =A6-serb_date | D6: Within 60d of lock-up | E6: If §1045 rollover executed
A7: =qsbs_5yr_date | B7: 5-YEAR QSBS THRESHOLD MET (Series B) | C7: =A7-serb_date | D7: 1826 days (5 yrs) | E7: §1202 exclusion NOW available
A8: =Inputs!$B$49 | B8: Evecxia IPO (estimated) | C8: =A8-serb_date | D8: Pre-readout | E8: If Evecxia goes public Q2 2027
A9: =ph3_date | B9: LBRX Phase 3 Topline (estimated) | C9: =A9-serb_date | D9: ~5.4 years | E9: CRITICAL: After May 3, 2027 → §1202 available
A10: =evecxia_ph2_date | B10: Evecxia Phase 2 OCD Readout (estimated) | C10: =A10-serb_date | D10: ~5.45 years | E10: §1045→§1202 chain value inflection

Sheet Comps
A1: COMPARABLE COMPANY ANALYSIS
A3: LBRX POST-PHASE 3 POSITIVE SCENARIOS
A4: Low: $1.5B mkt cap (~$50/share) — Conservative Phase 3 positive
A5: Base: $3.0B mkt cap (~$100/share) — Strong Phase 3 data + pipeline value
A6: High: $5.0B mkt cap (~$165/share) — Karuna-style M&A premium
A8: LBRX POST-PHASE 3 NEGATIVE SCENARIOS
A9: Low: $100M mkt cap (~$3.30/share) — Minerva-style wipeout
A10: Base: $200M mkt cap (~$6.60/share) — Cash floor + option value
A11: High: $350M mkt cap (~$11.50/share) — Modest decline, retry potential
A13: EVECXIA POST-PHASE 2 POSITIVE SCENARIOS
A14: Low: $800M — Modest positive data
A15: Base: $1.5B — Strong data validates platform (Karuna-like)
... A21: High: $250M — Borderline miss, dose issue, still fundable

Sheet Scenarios
A1: SCENARIO ANALYSIS
A3: Metric | B3: S1: Lock-Up Sale | C3: S2: Ph3+ Hold | D3: S3: Ph3- Hold | E3: S4: Dual Lot Lock-Up | F3: S5: §1045→Eve Ph2+ | G3: S6: §1045→Eve Ph2-
A5: Sale Date | B5: =lockup_date | C5: =ph3_date | D5: =ph3_date | E5: =lockup_date | F5: =evecxia_ph2_date | G5: =evecxia_ph2_date
A6: Sale Price / Share | B6: =lockup_price | C6: =Inputs!B53 | D6: =Inputs!B56 | E6: =lockup_price | F6: =Inputs!B59/Inputs!B65 | G6: =Inputs!B62/Inputs!B65
A7: Shares | B7: =serb_shares | C7: =serb_shares | D7: =serb_shares | E7: =serb_shares+IF(Inputs!B23="",0,Inputs!B25) | F7: =Inputs!B32 | G7: =Inputs!B32
A8: Gross Proceeds | B8: =B6*B7 | C8: =C6*C7 | D8: =D6*D7 | E8: =E6*E7 | F8: =F6*F7 | G8: =G6*G7
A9: Cost Basis | B9: =serb_basis | C9: =serb_basis | D9: =serb_basis | E9: =serb_basis+IF(Inputs!B23="",0,Inputs!B23) | F9: =serb_basis | G9: =serb_basis
A10: Gross Gain | B10: =B8-B9 | C10: =C8-C9 | D10: =D8-D9 | E10: =E8-E9 | F10: =F8-F9 | G10: =G8-G9
A11: Holding Period (days) | B11: =lockup_date-serb_date | C11: =ph3_date-serb_date | D11: =ph3_date-serb_date | E11: =lockup_date-serb_date | F11: =evecxia_ph2_date-serb_date | G11: =evecxia_ph2_date-serb_date
A12: Holding Period (years) | B12: =B11/365.25 | C12: =C11/365.25 | D12: =D11/365.25 | E12: =E11/365.25 | F12: =F11/365.25 | G12: =G11/365.25
A13: Long-Term? | B13: =IF(B11>365,"YES","NO") | C13: =IF(C11>365,"YES","NO") | D13: =IF(D11>365,"YES","NO") | E13: =IF(E11>365,"YES","NO") | F13: =IF(F11>365,"YES","NO") | G13: =IF(G11>365,"YES","NO")
A14: QSBS 5-Year Met? | B14: =IF(AND(B11>=1826,Inputs!B18="YES"),"YES","NO") | C14: =IF(AND(C11>=1826,Inputs!B18="YES"),"YES","NO") | D14: =IF(AND(D11>=1826,Inputs!B18="YES"),"YES","NO") | E14: =IF(AND(E11>=1826,Inputs!B18="YES"),"YES","NO") | F14: =IF(AND(F11>=1826,Inputs!B33="YES"),"YES","NO") | G14: =IF(AND(G11>=1826,Inputs!B33="YES"),"YES","NO")
A15: §1202 Exclusion | B15: =IF(B14="YES",MIN(B10,MAX(10000000,10*B9)),0) | C15: =IF(C14="YES",MIN(C10,MAX(10000000,10*C9)),0) | D15: =IF(D14="YES",MIN(MAX(0,D10),MAX(10000000,10*D9)),0) | E15: =IF(E14="YES",MIN(serb_shares*lockup_price-serb_basis,MAX(10000000,10*serb_basis)),0) | F15: =IF(F14="YES",MIN(F10,MAX(10000000,10*F9)),0) | G15: =IF(G14="YES",MIN(MAX(0,G10),MAX(10000000,10*G9)),0)
A16: §1045 Deferral | B16: 0 | C16: 0 | D16: 0 | E16: 0 | F16: =serb_shares*lockup_price-serb_basis | G16: =serb_shares*lockup_price-serb_basis
A17: Taxable Gain | B17: =MAX(0,B10-B15-B16) | C17: =MAX(0,C10-C15-C16) | D17: =MAX(0,D10-D15-D16) | E17: =MAX(0,E10-E15-E16) | F17: =MAX(0,F10-F15) | G17: =MAX(0,G10-G15)
A18: Federal Tax | B18: =IF(B13="YES",B17*eff_fed_rate,B17*Inputs!B11) | C18: =IF(C13="YES",C17*eff_fed_rate,C17*Inputs!B11) | D18: =IF(D13="YES",D17*eff_fed_rate,D17*Inputs!B11) | E18: =IF(E13="YES",E17*eff_fed_rate,E17*Inputs!B11) | F18: =IF(F13="YES",F17*eff_fed_rate,F17*Inputs!B11) | G18: =IF(G13="YES",G17*eff_fed_rate,G17*Inputs!B11)
A19: State Tax | B19: =B17*state_rate | C19: =C17*state_rate | D19: =D17*state_rate | E19: =E17*state_rate | F19: =F17*state_rate | G19: =G17*state_rate
A20: Total Tax | B20: =B18+B19 | C20: =C18+C19 | D20: =D18+D19 | E20: =E18+E19 | F20: =F18+F19 | G20: =G18+G19
A21: Net After-Tax | B21: =B8-B20 | C21: =C8-C20 | D21: =D8-D20 | E21: =E8-E20 | F21: =F8-F20 | G21: =G8-G20
A22: MOIC | B22: =B21/B9 | C22: =C21/C9 | D22: =D21/D9 | E22: =E21/E9 | F22: =F21/F9 | G22: =G21/G9
A23: Effective Tax Rate | B23: =IF(B10>0,B20/B10,0) | C23: =IF(C10>0,C20/C10,0) | D23: =IF(D10>0,D20/D10,0) | E23: =IF(E10>0,E20/E10,0) | F23: =IF(F10>0,F20/F10,0) | G23: =IF(G10>0,G20/G10,0)

Sheet TaxLogic
A1: TAX LOGIC ENGINE
A3: This sheet contains educational content on:
A4: • Standard capital gains tax calculation
A5: • §1202 QSBS exclusion rules and eligibility
A6: • §1045 rollover mechanics (8-step process)
A7: • Combined §1045→§1202 chain logic
A9: Key Rule: §1202 exclusion cap = greater of $10M or 10× original basis
A10: Key Rule: §1045 tacks holding period from original QSBS purchase date
A11: Key Rule: §1045 reduces basis in replacement stock by deferred gain

Sheet Decision Matrix
A1: DECISION MATRIX — PROBABILITY-WEIGHTED ANALYSIS
A3: CLINICAL PROBABILITY ASSUMPTIONS
A4: P(LBRX Phase 3 Success) | B4: 0.55 | C4: ← Adjustable (industry avg: 50-60%)
A5: P(Evecxia Phase 2 Success) | B5: 0.35 | C5: ← Adjustable (CNS Ph2: 30-40%)
A7: PATH 2: HOLD LBRX THROUGH PHASE 3
A8: Expected Net Value | B8: =0.55*Scenarios!C21+0.45*Scenarios!D21
A10: PATH 3: §1045 ROLL INTO EVECXIA
A11: Expected Net Value | B11: =0.35*Scenarios!F21+0.65*Scenarios!G21
A13: COMPARISON
A14: Path 2 Expected Value | B14: =B8
A15: Path 3 Expected Value | B15: =B11
A16: Difference (Path 3 - Path 2) | B16: =B15-B14

Sheet Breakeven
A1: BREAKEVEN ANALYSIS
A3: KEY QUESTION: AT WHAT EVECXIA VALUATION DOES PATH 3 = PATH 2?
A5: Path 2 Base Case Net (LBRX Ph3+ @ $100) | B5: =Scenarios!C21
A6: Investor Evecxia Shares | B6: =Inputs!B32
A7: Evecxia Total Shares at Readout | B7: =Inputs!B65
A8: Investor Ownership % | B8: =B6/B7
A10: Breakeven Evecxia Valuation (to match Path 2) | B10: =B5/B8
A12: Breakeven as Multiple of $180M IPO | B12: =B10/Inputs!B64

Sheet Dilution
A1: EVECXIA DILUTION WATERFALL
A2: Tracking investor ownership from Series A through Phase 2 readout
A4: Stage | B4: Total Shares | C4: Investor Shares | D4: Ownership % | E4: Stake Value
A5: Series A Close ($30M post-money) | B5: =Inputs!B36 | C5: =Inputs!B32 | D5: =C5/B5 | E5: =D5*Inputs!B35
A6: IPO ($180M valuation) | B6: =B5/0.80 | C6: =C5 | D6: =C6/B6 | E6: =D6*Inputs!B64
A7: At Phase 2 Readout (365M shares est.) | B7: =Inputs!B65 | C7: =C5 | D7: =C7/B7 | E7: varies by scenario

Sheet Outputs
A1: OUTPUTS DASHBOARD
A3: KEY FLAGS
A4: QSBS 5-year met at lock-up? | B4: =IF(lockup_date>=qsbs_5yr_date,"YES","NO")
A5: QSBS 5-year met at Phase 3 readout? | B5: =IF(ph3_date>=qsbs_5yr_date,"YES","NO")
A6: §1045 eligible? | B6: =IF(AND((lockup_date-serb_date)>180,Inputs!$B$33="YES"),"YES","NO")
A7: §1045 → §1202 chain achievable? | B7: =IF(AND(B6="YES",(evecxia_ph2_date-serb_date)>=1826),"YES","NO")
A9: SCENARIO COMPARISON
A10: Metric | B10: S1: Lock-Up | C10: S2: Ph3+ | D10: S3: Ph3- | E10: S4: Dual Lot | F10: S5: Eve+ | G10: S6: Eve-
A11: Gross Proceeds | B11: =Scenarios!B8 | C11: =Scenarios!C8 | D11: =Scenarios!D8 | E11: =Scenarios!E8 | F11: =Scenarios!F8 | G11: =Scenarios!G8
A12: Gain | B12: =Scenarios!B10 | C12: =Scenarios!C10 | D12: =Scenarios!D10 | E12: =Scenarios!E10 | F12: =Scenarios!F10 | G12: =Scenarios!G10
A13: §1202 Exclusion | B13: =Scenarios!B15 | C13: =Scenarios!C15 | D13: =Scenarios!D15 | E13: =Scenarios!E15 | F13: =Scenarios!F15 | G13: =Scenarios!G15
A14: Total Tax | B14: =Scenarios!B20 | C14: =Scenarios!C20 | D14: =Scenarios!D20 | E14: =Scenarios!E20 | F14: =Scenarios!F20 | G14: =Scenarios!G20
A15: Net After-Tax | B15: =Scenarios!B21 | C15: =Scenarios!C21 | D15: =Scenarios!D21 | E15: =Scenarios!E21 | F15: =Scenarios!F21 | G15: =Scenarios!G21
A16: MOIC | B16: =Scenarios!B22 | C16: =Scenarios!C22 | D16: =Scenarios!D22 | E16: =Scenarios!E22 | F16: =Scenarios!F22 | G16: =Scenarios!G22

Sheet Sources
A1: SOURCES & BIBLIOGRAPHY
A3: LBRX Current Stock Price - Yahoo Finance
A4: LBRX IPO Announcement - Cooley Press Release
A5: LBRX Phase 2 ILLUMINATE-1 - Globe Newswire
A6: Karuna BMY Acquisition - BMY Press Release
A7: ITCI JNJ Acquisition - JNJ Press Release
A8: Cerevel AbbVie Acquisition - AbbVie Press Release
A9: IRS §1202 QSBS Rules - IRS Publications
A10: IRS §1045 Rollover Rules - IRS Publication 550
